Workbook

Sheet Checklist manuelle
A1: Checklist de recette manuelle – périmètre final
A2: Fin de stage : seuls les tests essentiels sont conservés, avec leurs résultats réels et les anomalies identifiées.
A3: Test ID | B3: Priorité | C3: Rôle | D3: Module | E3: Précondition | F3: Données de test | G3: Étapes | H3: Résultat attendu | I3: Statut | J3: Résultat observé | K3: Sévérité anomalie | L3: Preuve / capture | M3: ID anomalie | N3: Commentaire
A4: AUTH-001 | B4: P0 | C4: Tous | D4: Authentification | E4: Backend et frontend lancés | F4: Compte valide du rôle | G4: 1. Ouvrir /login 2. Saisir email et mot de passe valides 3. Cliquer Se connecter | H4: Connexion réussie et redirection vers la route du rôle. | I4: Réussi | J4: La connexion a réussi avec les comptes de test et chaque utilisateur a été redirigé vers l’espace correspondant à son rôle.
A5: AUTH-002 | B5: P0 | C5: Tous | D5: Authentification | E5: Page /login ouverte | F5: Mot de passe incorrect | G5: Saisir un compte valide avec un mot de passe incorrect. | H5: Message d’erreur clair ; aucun token créé ; aucune redirection. | I5: Réussi | J5: La connexion avec un mot de passe incorrect a été refusée, un message d’erreur a été affiché et aucune redirection n’a eu lieu.
A6: AUTH-004 | B6: P0 | C6: Tous | D6: Sécurité | E6: Utilisateur déconnecté | F6: URL protégée du rôle | G6: Coller directement une URL protégée dans le navigateur. | H6: Redirection vers /login ; aucune donnée sensible affichée. | I6: Réussi | J6: L’ouverture directe d’une URL protégée sans session a redirigé vers /login sans afficher de donnée métier.
A7: AUTH-005 | B7: P0 | C7: Tous | D7: Routage | E7: Utilisateur connecté | F7: Routes attendues selon le rôle | G7: Se connecter successivement avec les 5 comptes. | H7: ADMIN→/admin ; ASSISTANTE→/assistante ; TECHNICO→/technico ; CHEF→/chef-chantier ; SOUS_TRAITANT→/sous-traitant. | I7: Réussi | J7: Les cinq comptes ont été redirigés vers les routes attendues : /admin, /assistante, /technico, /chef-chantier et /sous-traitant.
A8: ADM-001 | B8: P0 | C8: Admin | D8: Dashboard | E8: Données métier créées | F8: DEV-01, DEV-02, FACT-01, CHANT-01 | G8: Ouvrir /admin et vérifier chaque indicateur. | H8: Les compteurs et montants correspondent aux données. | I8: Réussi | J8: Le dashboard affiche les mêmes nombres que les pages Devis, Factures et Chantiers. Aucun écart constaté.
A9: ADM-002 | B9: P0 | C9: Admin | D9: Utilisateurs | E9: Compte Admin connecté | F9: Données des 3 nouveaux rôles | G9: Créer ou modifier un utilisateur de chaque rôle. | H9: Rôle, email, statut actif et mot de passe sont enregistrés. | I9: Réussi | J9: Les trois utilisateurs Assistante, Chef de chantier et Sous-traitant ont été créés avec le bon rôle et le statut Actif.
A10: ADM-003 | B10: P0 | C10: Admin | D10: Utilisateurs | E10: Utilisateur test existant | F10: Compte temporaire | G10: Désactiver le compte puis tenter de se connecter. | H10: Connexion refusée pour le compte désactivé. | I10: Réussi | J10: Compte désactivé
A11: ADM-004 | B11: P0 | C11: Admin | D11: Clients | E11: N/A | F11: CLI-01 | G11: Créer CLI-01 puis rechercher par nom et email. | H11: Client visible avec toutes les informations saisies. | I11: Réussi | J11: Le client Amina Test Admin a été créé et retrouvé par son nom et son email.
A12: ADM-005 | B12: P0 | C12: Admin | D12: Demandes | E12: CLI-01 créé | F12: DEM-01 | G12: Créer la demande puis filtrer par statut NOUVEAU. | H12: Demande visible, liée au bon client, statut NOUVEAU. | I12: Réussi | J12: La demande de devis a été créée pour Amina Test Admin, retrouvée dans la liste et affichée avec le statut Nouveau.
A13: ADM-006 | B13: P0 | C13: Admin | D13: Chantiers | E13: CLI-01 et DEV-01 disponibles | F13: CHANT-01 | G13: Créer CHANT-01 et affecter Julien Bernard. | H13: Chantier créé et visible dans l’espace Chef. | I13: Réussi | J13: Le chantier CHANT-ADM-MAN-001 a été créé et retrouvé dans l’espace Chef de chantier.
A14: ADM-007 | B14: P0 | C14: Admin | D14: Tâches chantier | E14: CHANT-01 créé | F14: TACH-01 à TACH-03 | G14: Affecter TACH-01 à l’Équipe interne principale et TACH-02/TACH-03 à Lucas Moreau. Vérifier les tâches dans les espaces Chef et Sous-traitant. | H14: La tâche interne est visible par le Chef et les deux tâches sous-traitant sont visibles uniquement par Lucas Moreau. | I14: Réussi | J14: La tâche Préparation chantier ADM-MAN a été affectée à l’Équipe interne principale et elle est visible dans l’espace Chef de chantier.
A15: ADM-008 | B15: P1 | C15: Admin | D15: Documents | E15: CHANT-01 et CHANT-02 créés | F15: DOC-01 à DOC-03 | G15: Ajouter les documents aux chantiers. | H15: Documents associés au bon chantier et téléchargeables. | I15: Échoué | J15: Aucune fonctionnalité ne permet d’ajouter un document à un chantier. La liste des chantiers propose uniquement les actions Modifier et Supprimer, et le formulaire de modification ne contient aucun champ ou onglet Documents. Il est donc impossible d’associer DOC-01, DOC-02 et DOC-03 aux chantiers ou de vérifier leur téléchargement. | K15: Haute | L15: Capture de la liste et du formulaire chantier sans section Documents | M15: BUG-ADM-008-01 | N15: Fonctionnalité Documents chantier absente de l’interface Admin.
A16: ADM-009 | B16: P0 | C16: Admin | D16: Catalogue | E16: N/A | F16: FOUR-01, MAT-01, MO-01, PRES-01 | G16: Créer fournisseur, matériau, main-d’œuvre et prestation. | H16: Toutes les entités sont enregistrées ; boutons principaux bleus. | I16: Réussi | J16: Le fournisseur, le matériau, le service de main-d’œuvre et la prestation de test ont été créés et retrouvés dans leurs listes. | N16: La création est validée. Les boutons Modifier du catalogue ne déclenchent actuellement aucune action ; voir BUG-ADM-CATALOGUE-EDIT-001.
A17: ADM-010 | B17: P1 | C17: Admin | D17: Compositions | E17: MAT-01, MO-01, PRES-01 créés | F17: Composition de PRES-01 | G17: Créer une composition combinant matériau et main-d’œuvre. | H17: Composition visible avec quantités et coûts cohérents. | I17: À tester
A18: ADM-EDIT-001 | B18: P1 | C18: Admin | D18: Catalogue / édition | E18: Matériau, main-d’œuvre, prestation et composition existants | F18: MAT-01, MO-01, PRES-01 | G18: Cliquer sur Modifier pour un matériau, un service de main-d’œuvre, une prestation et une composition. | H18: Une modale préremplie s’ouvre et la modification enregistrée reste visible après actualisation. | I18: Échoué | J18: Les icônes Modifier sont affichées mais ne déclenchent aucune ouverture de formulaire ni action de mise à jour. | K18: Haute | L18: Capture des listes Catalogue avec les icônes Modifier | M18: BUG-ADM-CATALOGUE-EDIT-001 | N18: Défaut commun aux pages Prestations, Compositions, Matériaux et Main-d’œuvre.
A19: ADM-012 | B19: P0 | C19: Admin | D19: Audit | E19: Au moins 5 modifications effectuées | F19: Actions précédentes | G19: Ouvrir Audit et filtrer par entité puis date. | H19: Anciennes/nouvelles valeurs et auteur sont affichés. | I19: Réussi | J19: L’Audit a affiché les actions exécutées avec l’auteur, la date et les anciennes/nouvelles valeurs disponibles.
A20: ADM-013 | B20: P1 | C20: Admin | D20: Base IA/RAG | E20: Compte Admin | F20: Document RAG de test | G20: Ajouter, modifier, désactiver puis rechercher un document. | H20: Opérations réussies et modal avec arrière-plan flou. | I20: À tester
A21: AST-001 | B21: P0 | C21: Assistante | D21: Routage | E21: Compte Assistante | F21: assistante@batiment-pro.fr | G21: Se connecter. | H21: Redirection /assistante, | I21: Réussi | J21: La connexion avec le compte Assistante a redirigé vers /assistante.
A22: AST-002 | B22: P0 | C22: Assistante | D22: Clients | E22: Compte Assistante | F22: CLI-03 | G22: Créer ou modifier CLI-03. | H22: Opération autorisée et données enregistrées. | I22: À tester
A23: AST-003 | B23: P0 | C23: Assistante | D23: Devis | E23: DEV-01 existant | F23: DEV-01 | G23: Consulter le devis et ses documents autorisés. | H23: Informations commerciales autorisées visibles. | I23: À tester
A24: AST-004 | B24: P0 | C24: Assistante | D24: Factures | E24: DEV-01 existant | F24: FACT-01 | G24: Créer/consulter FACT-01 et filtrer ENVOYEE. | H24: Facture visible et statut cohérent. | I24: À tester
A25: AST-005 | B25: P0 | C25: Assistante | D25: SAV | E25: SAV-02 | F25: SAV-02 | G25: Consulter, ajouter une note et changer un statut autorisé. | H25: Action enregistrée et visible dans l’historique. | I25: À tester
A26: AST-007 | B26: P0 | C26: Assistante | D26: Permissions | E26: Compte Assistante | F26: /admin/users | G26: Coller /admin/users directement. | H26: Accès refusé ou redirection ; aucune donnée utilisateur sensible. | I26: Réussi | J26: L’accès direct à /admin/users avec le compte Assistante a été refusé ou redirigé sans exposer les données utilisateurs.
A27: TEC-001 | B27: P0 | C27: Technico | D27: Routage | E27: Compte Technico | F27: technico@batiment-pro.fr | G27: Se connecter. | H27: Redirection /technico. | I27: Réussi | J27: La connexion avec le compte Technico a redirigé vers /technico.
A28: TEC-002 | B28: P0 | C28: Technico | D28: Clients | E28: N/A | F28: CLI-01 | G28: Créer CLI-01 puis ouvrir sa fiche. | H28: Client créé et fiche complète. | I28: À tester
A29: TEC-003 | B29: P0 | C29: Technico | D29: Demandes | E29: CLI-01 créé | F29: DEM-01 | G29: Créer une demande depuis la fiche client. | H29: Demande visible dans /technico/demandes. | I29: À tester
A30: TEC-004 | B30: P0 | C30: Technico | D30: Demandes | E30: DEM-01 au statut NOUVEAU | F30: DEM-01 | G30: Cliquer Générer le devis. | H30: Statut passe EN_COURS et navigation vers la checklist. | I30: À tester
A31: TEC-005 | B31: P0 | C31: Technico | D31: Checklist devis | E31: DEM-01 en cours | F31: Besoins de DEM-01 | G31: Compléter les informations nécessaires. | H31: Checklist sauvegardée sans perte de données. | I31: À tester
A32: TEC-006 | B32: P0 | C32: Technico | D32: Devis | E32: Checklist complétée | F32: DEV-01 | G32: Générer puis ouvrir le devis. | H32: Devis lié à DEM-01 et CLI-01. | I32: À tester
A33: TEC-007 | B33: P0 | C33: Technico | D33: Devis | E33: DEV-01 créé | F33: DEV-01 | G33: Modifier une quantité et recalculer. | H33: HT, TVA, TTC, coût et marge sont recalculés. | I33: À tester
A34: TEC-009 | B34: P0 | C34: Technico | D34: Signature | E34: DEV-01 prêt | F34: Téléphone CLI-01 | G34: Lancer le flux de signature autorisé. | H34: Demande de signature créée et statut cohérent. | I34: À tester
A35: TEC-012 | B35: P1 | C35: Technico | D35: Assistant IA | E35: Documents RAG disponibles | F35: Question liée aux prestations | G35: Poser une question métier. | H35: Réponse utile, sans donnée sensible ni hallucination manifeste. | I35: À tester
A36: TEC-013 | B36: P0 | C36: Technico | D36: Permissions | E36: Compte Technico | F36: /admin/users et /admin/audit | G36: Tenter les accès directs. | H36: Accès refusés. | I36: Réussi | J36: Les accès directs du Technico aux pages Admin Utilisateurs et Audit ont été refusés.
A37: CHEF-001 | B37: P0 | C37: Chef de chantier | D37: Routage | E37: Compte Chef | F37: chef.chantier@batiment-pro.fr | G37: Se connecter. | H37: Redirection /chef-chantier | I37: Réussi | J37: La connexion avec le compte Chef de chantier a redirigé vers /chef-chantier.
A38: CHEF-002 | B38: P0 | C38: Chef de chantier | D38: Dashboard | E38: CHANT-01 affecté | F38: CHANT-01 | G38: Ouvrir le dashboard. | H38: CHANT-01 et ses compteurs sont visibles. | I38: Réussi | J38: Le dashboard Chef a affiché le chantier affecté ainsi que ses compteurs.
A39: CHEF-003 | B39: P0 | C39: Chef de chantier | D39: Isolation chantiers | G39: Ouvrir Mes chantiers. | H39: Affichage ces chantiers de chef chantier | I39: Réussi | J39: La page Mes chantiers a affiché uniquement les chantiers accessibles au Chef connecté.
A40: CHEF-004 | B40: P0 | C40: Chef de chantier | D40: Tâches | E40: TACH-01 affectée | F40: TACH-01 | G40: Ouvrir Tâches chantier. | H40: TACH-01 visible avec statut et avancement. | I40: Réussi | J40: La tâche interne affectée au Chef était visible avec son état dans l’espace Tâches chantier.
...

Sheet Jeu de données
A1: Jeu de données de recette
A3: Code | B3: Ordre | C3: Entité | D3: Nom / Référence | E3: Dépend de | F3: Statut initial | G3: Responsable / Affectation | H3: Valeurs à saisir | I3: Utilisation dans les tests
A4: TP-01 | B4: 1 | C4: Type de projet | D4: Rénovation salle de bain | F4: ACTIF | G4: Admin | H4: Description : Rénovation complète d’une salle de bain. | I4: Création et sélection dans les fiches clients
A5: TP-02 | B5: 2 | C5: Type de projet | D5: Rénovation cuisine | F5: ACTIF | G5: Admin | H5: Description : Rénovation complète d’une cuisine. | I5: Filtrage et choix d’un second type
A6: CLI-01 | B6: 3 | C6: Client | D6: Amina Ben Salah | F6: ACTIF | G6: Technico | H6: Prénom=Amina ; Nom=Ben Salah ; Email=amina.tests+crm@example.com ; Téléphone=20111222 ; Adresse client=12 rue des Jasmins, Tunis ; Adresse chantier=8 avenue Habib Bourguiba, La Marsa ; Source=SITE_WEB ; Type projet=TP-01 | I6: Parcours nominal Client → Demande → Devis → Chantier
A7: CLI-02 | B7: 4 | C7: Client | D7: Hatem Trabelsi | F7: ACTIF | G7: Admin | H7: Email=hatem.tests+crm@example.com ; Téléphone=22333444 ; Adresse client=5 rue de Carthage, Tunis ; Adresse chantier=22 rue du Lac, Les Berges du Lac ; Source=APPEL ; Type projet=TP-02 | I7: Chantier non affecté pour test d’isolation Chef/Sous-traitant
A8: CLI-03 | B8: 5 | C8: Client | D8: Leïla Gharbi | F8: ACTIF | G8: Assistante | H8: Email=leila.tests+crm@example.com ; Téléphone=24555666 ; Adresse client=10 avenue de France, Ariana ; Source=RECOMMANDATION ; Type projet=TP-01 | I8: Tests Assistante et recherche client
A9: DEM-01 | B9: 6 | C9: Demande de devis | D9: Demande salle de bain Amina | E9: CLI-01 | F9: NOUVEAU | G9: Technico | H9: Description : Remplacement baignoire par douche italienne, carrelage mural, meuble vasque et éclairage. Budget indicatif : 18 000 TND. Délai souhaité : 6 semaines. | I9: Tester passage NOUVEAU → EN_COURS et génération du devis
A10: DEM-02 | B10: 7 | C10: Demande de devis | D10: Demande cuisine Hatem | E10: CLI-02 | F10: EN_COURS | G10: Technico | H10: Description : Cuisine complète 14 m², meubles, plan de travail, plomberie et électricité. | I10: Tester filtre EN_COURS et accès aux détails
A11: DEV-01 | B11: 8 | C11: Devis | D11: Devis Amina – version initiale | E11: CLI-01 / DEM-01 | F11: BROUILLON | G11: Technico | H11: Taux TVA=20% ; 2 à 4 lignes de prestations ; Total cible entre 15 000 et 20 000 TND ; Notes=Validité 30 jours. | I11: Modifier, recalculer, envoyer et accepter le devis
A12: DEV-02 | B12: 9 | C12: Devis | D12: Devis Hatem – refusé | E12: CLI-02 / DEM-02 | F12: REFUSE | G12: Technico | H12: Total cible=28 500 TND ; motif de refus à noter dans les commentaires. | I12: Dashboard, filtres de devis et audit
A13: FACT-01 | B13: 10 | C13: Facture | D13: Facture finale Amina | E13: DEV-01 | F13: ENVOYEE | G13: Assistante | H13: Échéance dépassée de 5 jours ; montant TTC basé sur DEV-01 ; email client=amina.tests+crm@example.com. | I13: Tester facture impayée et notification
A14: FACT-02 | B14: 11 | C14: Facture | D14: Facture payée Hatem | E14: DEV-02 | F14: PAYEE | G14: Assistante | H14: Date paiement renseignée ; montant TTC basé sur DEV-02. | I14: Tester filtres PAYEE / ENVOYEE
A15: CHANT-01 | B15: 12 | C15: Chantier | D15: Chantier Amina – La Marsa | E15: CLI-01 / DEV-01 | F15: PLANIFIE | G15: Chef : Julien Bernard | H15: Adresse=8 avenue Habib Bourguiba, La Marsa ; Description=Rénovation salle de bain ; Date début=prochain lundi ; Date fin=+30 jours. | I15: Doit être visible par le Chef et le Sous-traitant si une tâche lui est affectée
A16: CHANT-02 | B16: 13 | C16: Chantier | D16: Chantier Hatem – Lac | E16: CLI-02 / DEV-02 | F16: VISITE_TECHNIQUE | G16: Non affecté | H16: Adresse=22 rue du Lac, Les Berges du Lac ; Description=Rénovation cuisine. | I16: Ne doit pas être visible par Chef/Sous-traitant
A17: TACH-01 | B17: 14 | C17: Tâche chantier | D17: Préparation et sécurisation du chantier | E17: CHANT-01 | F17: A_FAIRE | G17: Chef : Julien Bernard | H17: Avancement=0 ; Date début=prochain lundi ; Date fin=+2 jours ; Ordre=1. | I17: Chef : changement statut, avancement et commentaire
A18: TACH-02 | B18: 15 | C18: Tâche chantier | D18: Pose du carrelage mural | E18: CHANT-01 | F18: A_FAIRE | G18: Sous-traitant : Lucas Moreau | H18: Avancement=0 ; Date début=+7 jours ; Date fin=+12 jours ; Ordre=2. | I18: Sous-traitant : mise à jour et isolation des tâches
A19: TACH-03 | B19: 16 | C19: Tâche chantier | D19: Installation meuble vasque | E19: CHANT-01 | F19: BLOQUEE | G19: Sous-traitant : Lucas Moreau | H19: Avancement=25 ; Commentaire=En attente de livraison du meuble. | I19: Tester statut BLOQUEE et reprise EN_COURS
A20: TACH-04 | B20: 17 | C20: Tâche chantier | D20: Mesures cuisine | E20: CHANT-02 | F20: A_FAIRE | G20: Non affecté | H20: Avancement=0. | I20: Ne doit pas apparaître chez Chef/Sous-traitant
... A25: SAV-02 | B25: 22 | C25: Ticket SAV | D25: Question facture | E25: CLI-03 / FACT-01 | F25: EN_ATTENTE_CLIENT | G25: Assigné Assistante | H25: Priorité=NORMALE ; Catégorie=FACTURATION. | I25: Filtres SAV et notes internes
A26: DEMO-01 | B26: 23 | C26: Demande de démo | D26: Nadia Khelifi – Studio NK | F26: PENDING | G26: Non affectée | H26: Email=nadia.demo+crm@example.com ; Téléphone=25123456 ; Entreprise=Studio NK ; Message=Demande de démonstration du CRM. | I26: Formulaire public → back-office → notification
A27: DEMO-02 | B27: 24 | C27: Demande de démo | D27: Karim Mansour – KM Bâtiment | F27: SCHEDULED | G27: Assignée Technico | H27: Email=karim.demo+crm@example.com ; Date démo=demain 15:00. | I27: Filtres et changement de statut
A28: FOUR-01 | B28: 25 | C28: Fournisseur | D28: Céramique Plus | F28: ACTIF | G28: Admin | H28: Contact=Salma Jaziri ; Email=fournisseur.tests+crm@example.com ; Téléphone=71111222 ; Types matériaux=Carrelage, colle, joints ; Délai=5 jours. | I28: Tests fournisseurs, matériaux et commandes
A29: MAT-01 | B29: 26 | C29: Matériau | D29: Carrelage mural blanc 30x60 | E29: FOUR-01 | F29: ACTIF | G29: Admin | H29: Unité=M2 ; Prix achat fixe=35.000 ; Couleur=Blanc ; Finition=Mate. | I29: Catalogue et devis
A30: MO-01 | B30: 27 | C30: Main-d’œuvre | D30: Pose carrelage mural | F30: ACTIF | G30: Admin | H30: Unité=M2 ; Prix unitaire=22.000 ; Productivité/jour=12. | I30: Catalogue, composition et devis
A31: PRES-01 | B31: 28 | C31: Prestation | D31: Fourniture et pose carrelage mural | E31: MAT-01 / MO-01 | F31: ACTIF | G31: Admin | H31: Unité=M2 ; Prix vente min=65.000 ; Prix vente max=85.000 ; Catégorie=Revêtements. | I31: Composition et ligne de devis

Sheet Comptes de test
A1: Comptes de test
A3: Rôle | B3: Utilisateur | C3: Email | D3: Mot de passe | E3: Route attendue | F3: Accès attendu | G3: Note
A4: ADMIN | B4: Super Admin | C4: admin@batiment-pro.fr | D4: Admin@2026! | E4: /admin | F4: Accès complet : dashboard, utilisateurs, audit, catalogue, SAV, démo, paramètres. | G4: Compte de développement uniquement
A5: TECHNICO | B5: Marc Dupont | C5: technico@batiment-pro.fr | D5: Technico@2026! | E5: /technico | F5: Clients, demandes, devis, factures, commandes, SAV, assistant IA, catalogue autorisé. | G5: Ne doit pas accéder à la gestion des utilisateurs ni à l’audit réservé Admin
A6: ASSISTANTE | B6: Sophie Martin | C6: assistante@batiment-pro.fr | D6: Assistante@2026! | E6: /assistante | F6: Clients, demandes, devis, factures, documents, SAV et demandes de démo selon permissions. | G6: Ne doit pas accéder aux fonctions sensibles réservées Admin
A7: CHEF_CHANTIER | B7: Julien Bernard | C7: chef.chantier@batiment-pro.fr | D7: ChefChantier@2026! | E7: /chef-chantier | F7: Uniquement les chantiers, tâches, réceptions, documents et SAV qui lui sont affectés. | G7: Tester impérativement l’isolation des données
A8: SOUS_TRAITANT | B8: Lucas Moreau | C8: sous.traitant@batiment-pro.fr | D8: SousTraitant@2026! | E8: /sous-traitant | F8: Uniquement ses tâches, chantiers liés et documents autorisés. | G8: Ne doit jamais être redirigé vers /fournisseur
A10: Sécurité
A11: Attention | B11: Ces mots de passe servent uniquement au développement et aux tests. Ne pas pousser ce fichier dans un dépôt public.

Sheet Anomalies
A1: Registre des anomalies – recette finale
A2: Anomalies confirmées pendant la recette manuelle et conservées dans le livrable de fin de stage.
A4: ID anomalie | B4: Test ID | C4: Module | D4: Titre | E4: Résultat observé | F4: Résultat attendu | G4: Sévérité | H4: Statut | I4: Preuve / capture | J4: Commentaire
A5: BUG-ADM-008-01 | B5: ADM-008 | C5: Documents | D5: Gestion des documents chantier absente | E5: Aucune fonctionnalité ne permet d’ajouter un document à un chantier. La liste propose uniquement Modifier et Supprimer, et le formulaire chantier ne contient aucun champ ou onglet Documents. | F5: L’Admin doit pouvoir ajouter DOC-01 à DOC-03 aux chantiers concernés, puis les consulter et les télécharger. | G5: Haute | H5: Ouverte | I5: Capture de la liste et du formulaire chantier sans section Documents | J5: Fonctionnalité Documents chantier absente de l’interface Admin.
A6: BUG-ADM-CATALOGUE-EDIT-001 | B6: ADM-EDIT-001 | C6: Catalogue / édition | D6: Boutons Modifier inactifs | E6: Les icônes Modifier des pages Prestations, Compositions, Matériaux et Main-d’œuvre sont visibles, mais aucun formulaire ne s’ouvre et aucune action de mise à jour n’est exécutée. | F6: Une modale préremplie doit s’ouvrir et les modifications enregistrées doivent rester visibles après actualisation. | G6: Haute | H6: Ouverte | I6: Capture des listes Catalogue avec les icônes Modifier | J6: Défaut commun aux pages Prestations, Compositions, Matériaux et Main-d’œuvre.

Sheet Résumé
A1: Tableau de suivi – recette finale
A3: Indicateur | B3: Valeur | D3: Statut | E3: Nombre
A4: Total des tests essentiels | B4: =COUNTA('Checklist manuelle'!$A$4:$A$500) -> 62 | D4: À tester | E4: =COUNTIF('Checklist manuelle'!$I$4:$I$500,"À tester") -> 17
A5: Tests P0 | B5: =COUNTIF('Checklist manuelle'!$B$4:$B$500,"P0") -> 56 | D5: En cours | E5: =COUNTIF('Checklist manuelle'!$I$4:$I$500,"En cours") -> 3
A6: Tests P1 | B6: =COUNTIF('Checklist manuelle'!$B$4:$B$500,"P1") -> 6 | D6: Réussi | E6: =COUNTIF('Checklist manuelle'!$I$4:$I$500,"Réussi") -> 40
A7: Tests terminés | B7: =COUNTIF('Checklist manuelle'!$I$4:$I$500,"Réussi")+COUNTIF('Checklist manuelle'!$I$4:$I$500,"Échoué") -> 42 | D7: Échoué | E7: =COUNTIF('Checklist manuelle'!$I$4:$I$500,"Échoué") -> 2
A8: Tests restant à exécuter | B8: =COUNTIF('Checklist manuelle'!$I$4:$I$500,"À tester")+COUNTIF('Checklist manuelle'!$I$4:$I$500,"En cours")+COUNTIF('Checklist manuelle'!$I$4:$I$500,"Bloqué") -> 20 | D8: Bloqué | E8: =COUNTIF('Checklist manuelle'!$I$4:$I$500,"Bloqué") -> 0
A9: Anomalies ouvertes | B9: =COUNTIF(Anomalies!$H$5:$H$100,"Ouverte")+COUNTIF(Anomalies!$H$5:$H$100,"En cours") -> 2
A12: Rôle impliqué | B12: Total | C12: Réussis | D12: Échoués | E12: À faire / en cours | F12: Progression
A13: Admin | B13: =COUNTIF('Checklist manuelle'!$C$4:$C$500,"Admin")+COUNTIF('Checklist manuelle'!$C$4:$C$500,"Admin/Technico")+COUNTIF('Checklist manuelle'!$C$4:$C$500,"Admin/Assistante/Technico")+COUNTIF('Checklist manuelle'!$C$4:$C$500,"Admin/Assistante") -> 19 | C13: =COUNTIFS('Checklist manuelle'!$C$4:$C$500,"Admin",'Checklist manuelle'!$I$4:$I$500,"Réussi")+COUNTIFS('Checklist manuelle'!$C$4:$C$500,"Admin/Technico",'Checklist manuelle'!$I$4:$I$500,"Réussi")+COUNTIFS('Checklist manuelle'!$C$4:$C$500,"Admin/Assistante/Technico",'Checklist manuelle'!$I$4:$I$500,"Réussi")+COUNTIFS('Checklist manuelle'!$C$4:$C$500,"Admin/Assistante",'Checklist manuelle'!$I$4:$I$500,"Réussi") -> 13 | D13: =COUNTIFS('Checklist manuelle'!$C$4:$C$500,"Admin",'Checklist manuelle'!$I$4:$I$500,"Échoué")+COUNTIFS('Checklist manuelle'!$C$4:$C$500,"Admin/Technico",'Checklist manuelle'!$I$4:$I$500,"Échoué")+COUNTIFS('Checklist manuelle'!$C$4:$C$500,"Admin/Assistante/Technico",'Checklist manuelle'!$I$4:$I$500,"Échoué")+COUNTIFS('Checklist manuelle'!$C$4:$C$500,"Admin/Assistante",'Checklist manuelle'!$I$4:$I$500,"Échoué") -> 2 | E13: =COUNTIFS('Checklist manuelle'!$C$4:$C$500,"Admin",'Checklist manuelle'!$I$4:$I$500,"À tester")+COUNTIFS('Checklist manuelle'!$C$4:$C$500,"Admin/Technico",'Checklist manuelle'!$I$4:$I$500,"À tester")+COUNTIFS('Checklist manuelle'!$C$4:$C$500,"Admin/Assistante/Technico",'Checklist manuelle'!$I$4:$I$500,"À tester")+COUNTIFS('Checklist manuelle'!$C$4:$C$500,"Admin/Assistante",'Checklist manuelle'!$I$4:$I$500,"À tester")+COUNTIFS('Checklist manuelle'!$C$4:$C$500,"Admin",'Checklist manuelle'!$I$4:$I$500,"En cours")+COUNTIFS('Checklist manuelle'!$C$4:$C$500,"Admin/Technico",'Checklist manuelle'!$I$4:$I$500,"En cours")+COUNTIFS('Checklist manuelle'!$C$4:$C$500,"Admin/Assistante/Technico",'Checklist manuelle'!$I$4:$I$500,"En cours")+COUNTIFS('Checklist manuelle'!$C$4:$C$500,"Admin/Assistante",'Checklist manuelle'!$I$4:$I$500,"En cours")+COUNTIFS('Checklist manuelle'!$C$4:$C$500,"Admin",'Checklist manuelle'!$I$4:$I$500,"Bloqué")+COUNTIFS('Checklist manuelle'!$C$4:$C$500,"Admin/Technico",'Checklist manuelle'!$I$4:$I$500,"Bloqué")+COUNTIFS('Checklist manuelle'!$C$4:$C$500,"Admin/Assistante/Technico",'Checklist manuelle'!$I$4:$I$500,"Bloqué")+COUNTIFS('Checklist manuelle'!$C$4:$C$500,"Admin/Assistante",'Checklist manuelle'!$I$4:$I$500,"Bloqué") -> 4 | F13: =IF(B13=0,0,C13/B13) -> 0.68421053
A14: Assistante | B14: =COUNTIF('Checklist manuelle'!$C$4:$C$500,"Assistante")+COUNTIF('Checklist manuelle'!$C$4:$C$500,"Admin/Assistante/Technico")+COUNTIF('Checklist manuelle'!$C$4:$C$500,"Admin/Assistante") -> 9 | C14: =COUNTIFS('Checklist manuelle'!$C$4:$C$500,"Assistante",'Checklist manuelle'!$I$4:$I$500,"Réussi")+COUNTIFS('Checklist manuelle'!$C$4:$C$500,"Admin/Assistante/Technico",'Checklist manuelle'!$I$4:$I$500,"Réussi")+COUNTIFS('Checklist manuelle'!$C$4:$C$500,"Admin/Assistante",'Checklist manuelle'!$I$4:$I$500,"Réussi") -> 3 | D14: =COUNTIFS('Checklist manuelle'!$C$4:$C$500,"Assistante",'Checklist manuelle'!$I$4:$I$500,"Échoué")+COUNTIFS('Checklist manuelle'!$C$4:$C$500,"Admin/Assistante/Technico",'Checklist manuelle'!$I$4:$I$500,"Échoué")+COUNTIFS('Checklist manuelle'!$C$4:$C$500,"Admin/Assistante",'Checklist manuelle'!$I$4:$I$500,"Échoué") -> 0 | E14: =COUNTIFS('Checklist manuelle'!$C$4:$C$500,"Assistante",'Checklist manuelle'!$I$4:$I$500,"À tester")+COUNTIFS('Checklist manuelle'!$C$4:$C$500,"Admin/Assistante/Technico",'Checklist manuelle'!$I$4:$I$500,"À tester")+COUNTIFS('Checklist manuelle'!$C$4:$C$500,"Admin/Assistante",'Checklist manuelle'!$I$4:$I$500,"À tester")+COUNTIFS('Checklist manuelle'!$C$4:$C$500,"Assistante",'Checklist manuelle'!$I$4:$I$500,"En cours")+COUNTIFS('Checklist manuelle'!$C$4:$C$500,"Admin/Assistante/Technico",'Checklist manuelle'!$I$4:$I$500,"En cours")+COUNTIFS('Checklist manuelle'!$C$4:$C$500,"Admin/Assistante",'Checklist manuelle'!$I$4:$I$500,"En cours")+COUNTIFS('Checklist manuelle'!$C$4:$C$500,"Assistante",'Checklist manuelle'!$I$4:$I$500,"Bloqué")+COUNTIFS('Checklist manuelle'!$C$4:$C$500,"Admin/Assistante/Technico",'Checklist manuelle'!$I$4:$I$500,"Bloqué")+COUNTIFS('Checklist manuelle'!$C$4:$C$500,"Admin/Assistante",'Checklist manuelle'!$I$4:$I$500,"Bloqué") -> 6 | F14: =IF(B14=0,0,C14/B14) -> 0.33333333
A15: Technico | B15: =COUNTIF('Checklist manuelle'!$C$4:$C$500,"Technico")+COUNTIF('Checklist manuelle'!$C$4:$C$500,"Admin/Technico")+COUNTIF('Checklist manuelle'!$C$4:$C$500,"Admin/Assistante/Technico")+COUNTIF('Checklist manuelle'!$C$4:$C$500,"Technico/Chef de chantier") -> 17 | C15: =COUNTIFS('Checklist manuelle'!$C$4:$C$500,"Technico",'Checklist manuelle'!$I$4:$I$500,"Réussi")+COUNTIFS('Checklist manuelle'!$C$4:$C$500,"Admin/Technico",'Checklist manuelle'!$I$4:$I$500,"Réussi")+COUNTIFS('Checklist manuelle'!$C$4:$C$500,"Admin/Assistante/Technico",'Checklist manuelle'!$I$4:$I$500,"Réussi")+COUNTIFS('Checklist manuelle'!$C$4:$C$500,"Technico/Chef de chantier",'Checklist manuelle'!$I$4:$I$500,"Réussi") -> 7 | D15: =COUNTIFS('Checklist manuelle'!$C$4:$C$500,"Technico",'Checklist manuelle'!$I$4:$I$500,"Échoué")+COUNTIFS('Checklist manuelle'!$C$4:$C$500,"Admin/Technico",'Checklist manuelle'!$I$4:$I$500,"Échoué")+COUNTIFS('Checklist manuelle'!$C$4:$C$500,"Admin/Assistante/Technico",'Checklist manuelle'!$I$4:$I$500,"Échoué")+COUNTIFS('Checklist manuelle'!$C$4:$C$500,"Technico/Chef de chantier",'Checklist manuelle'!$I$4:$I$500,"Échoué") -> 0 | E15: =COUNTIFS('Checklist manuelle'!$C$4:$C$500,"Technico",'Checklist manuelle'!$I$4:$I$500,"À tester")+COUNTIFS('Checklist manuelle'!$C$4:$C$500,"Admin/Technico",'Checklist manuelle'!$I$4:$I$500,"À tester")+COUNTIFS('Checklist manuelle'!$C$4:$C$500,"Admin/Assistante/Technico",'Checklist manuelle'!$I$4:$I$500,"À tester")+COUNTIFS('Checklist manuelle'!$C$4:$C$500,"Technico/Chef de chantier",'Checklist manuelle'!$I$4:$I$500,"À tester")+COUNTIFS('Checklist manuelle'!$C$4:$C$500,"Technico",'Checklist manuelle'!$I$4:$I$500,"En cours")+COUNTIFS('Checklist manuelle'!$C$4:$C$500,"Admin/Technico",'Checklist manuelle'!$I$4:$I$500,"En cours")+COUNTIFS('Checklist manuelle'!$C$4:$C$500,"Admin/Assistante/Technico",'Checklist manuelle'!$I$4:$I$500,"En cours")+COUNTIFS('Checklist manuelle'!$C$4:$C$500,"Technico/Chef de chantier",'Checklist manuelle'!$I$4:$I$500,"En cours")+COUNTIFS('Checklist manuelle'!$C$4:$C$500,"Technico",'Checklist manuelle'!$I$4:$I$500,"Bloqué")+COUNTIFS('Checklist manuelle'!$C$4:$C$500,"Admin/Technico",'Checklist manuelle'!$I$4:$I$500,"Bloqué")+COUNTIFS('Checklist manuelle'!$C$4:$C$500,"Admin/Assistante/Technico",'Checklist manuelle'!$I$4:$I$500,"Bloqué")+COUNTIFS('Checklist manuelle'!$C$4:$C$500,"Technico/Chef de chantier",'Checklist manuelle'!$I$4:$I$500,"Bloqué") -> 10 | F15: =IF(B15=0,0,C15/B15) -> 0.41176471
A16: Chef de chantier | B16: =COUNTIF('Checklist manuelle'!$C$4:$C$500,"Chef de chantier")+COUNTIF('Checklist manuelle'!$C$4:$C$500,"Technico/Chef de chantier") -> 7 | C16: =COUNTIFS('Checklist manuelle'!$C$4:$C$500,"Chef de chantier",'Checklist manuelle'!$I$4:$I$500,"Réussi")+COUNTIFS('Checklist manuelle'!$C$4:$C$500,"Technico/Chef de chantier",'Checklist manuelle'!$I$4:$I$500,"Réussi") -> 7 | D16: =COUNTIFS('Checklist manuelle'!$C$4:$C$500,"Chef de chantier",'Checklist manuelle'!$I$4:$I$500,"Échoué")+COUNTIFS('Checklist manuelle'!$C$4:$C$500,"Technico/Chef de chantier",'Checklist manuelle'!$I$4:$I$500,"Échoué") -> 0 | E16: =COUNTIFS('Checklist manuelle'!$C$4:$C$500,"Chef de chantier",'Checklist manuelle'!$I$4:$I$500,"À tester")+COUNTIFS('Checklist manuelle'!$C$4:$C$500,"Technico/Chef de chantier",'Checklist manuelle'!$I$4:$I$500,"À tester")+COUNTIFS('Checklist manuelle'!$C$4:$C$500,"Chef de chantier",'Checklist manuelle'!$I$4:$I$500,"En cours")+COUNTIFS('Checklist manuelle'!$C$4:$C$500,"Technico/Chef de chantier",'Checklist manuelle'!$I$4:$I$500,"En cours")+COUNTIFS('Checklist manuelle'!$C$4:$C$500,"Chef de chantier",'Checklist manuelle'!$I$4:$I$500,"Bloqué")+COUNTIFS('Checklist manuelle'!$C$4:$C$500,"Technico/Chef de chantier",'Checklist manuelle'!$I$4:$I$500,"Bloqué") -> 0 | F16: =IF(B16=0,0,C16/B16) -> 1
A17: Sous-traitant | B17: =COUNTIF('Checklist manuelle'!$C$4:$C$500,"Sous-traitant") -> 11 | C17: =COUNTIFS('Checklist manuelle'!$C$4:$C$500,"Sous-traitant",'Checklist manuelle'!$I$4:$I$500,"Réussi") -> 8 | D17: =COUNTIFS('Checklist manuelle'!$C$4:$C$500,"Sous-traitant",'Checklist manuelle'!$I$4:$I$500,"Échoué") -> 0 | E17: =COUNTIFS('Checklist manuelle'!$C$4:$C$500,"Sous-traitant",'Checklist manuelle'!$I$4:$I$500,"À tester")+COUNTIFS('Checklist manuelle'!$C$4:$C$500,"Sous-traitant",'Checklist manuelle'!$I$4:$I$500,"En cours")+COUNTIFS('Checklist manuelle'!$C$4:$C$500,"Sous-traitant",'Checklist manuelle'!$I$4:$I$500,"Bloqué") -> 3 | F17: =IF(B17=0,0,C17/B17) -> 0.72727273
A18: Tous / Public | B18: =COUNTIF('Checklist manuelle'!$C$4:$C$500,"Tous")+COUNTIF('Checklist manuelle'!$C$4:$C$500,"Public") -> 7 | C18: =COUNTIFS('Checklist manuelle'!$C$4:$C$500,"Tous",'Checklist manuelle'!$I$4:$I$500,"Réussi")+COUNTIFS('Checklist manuelle'!$C$4:$C$500,"Public",'Checklist manuelle'!$I$4:$I$500,"Réussi") -> 6 | D18: =COUNTIFS('Checklist manuelle'!$C$4:$C$500,"Tous",'Checklist manuelle'!$I$4:$I$500,"Échoué")+COUNTIFS('Checklist manuelle'!$C$4:$C$500,"Public",'Checklist manuelle'!$I$4:$I$500,"Échoué") -> 0 | E18: =COUNTIFS('Checklist manuelle'!$C$4:$C$500,"Tous",'Checklist manuelle'!$I$4:$I$500,"À tester")+COUNTIFS('Checklist manuelle'!$C$4:$C$500,"Public",'Checklist manuelle'!$I$4:$I$500,"À tester")+COUNTIFS('Checklist manuelle'!$C$4:$C$500,"Tous",'Checklist manuelle'!$I$4:$I$500,"En cours")+COUNTIFS('Checklist manuelle'!$C$4:$C$500,"Public",'Checklist manuelle'!$I$4:$I$500,"En cours")+COUNTIFS('Checklist manuelle'!$C$4:$C$500,"Tous",'Checklist manuelle'!$I$4:$I$500,"Bloqué")+COUNTIFS('Checklist manuelle'!$C$4:$C$500,"Public",'Checklist manuelle'!$I$4:$I$500,"Bloqué") -> 1 | F18: =IF(B18=0,0,C18/B18) -> 0.85714286
